Workbook

Sheet 30 puntos (cm)
A1: Regresión lineal por mínimos cuadrados
A2: Valor inicial de x (cm) | B2: 100
A3: Paso entre puntos (cm) | B3: 10
A6: Observación | B6: Distancia x (cm) | C6: y | D6: xy | E6: x^2 | F6: Y modelo | G6: (Y - Ymodelo)^2 | H6: y - yprom | I6: (Y-Yprom)^2 | J6: x - xprom | K6: (x-xprom)^2 | L6: (x-xprom)(y-yprom) | N6: Resumen | O6: Valor
A7: 1 | B7: =$B$2+$B$3*(A7-1) -> 100 | C7: -49.9 | D7: =IF(C7="","",B7*C7) -> -4990 | E7: =IF(C7="","",B7^2) -> 10000 | F7: =IF(C7="","",$O$15*B7+$O$16) -> -50.184516 | G7: =IF(C7="","",(C7-F7)^2) -> 0.080949428 | H7: =IF(C7="","",C7-$O$11) -> 10.24 | I7: =IF(C7="","",H7^2) -> 104.8576 | J7: =IF(C7="","",B7-$O$10) -> -145 | K7: =IF(C7="","",J7^2) -> 21025 | L7: =IF(C7="","",J7*H7) -> -1484.8 | N7: n | O7: =COUNT(C7:C36) -> 30
A8: 2 | B8: =$B$2+$B$3*(A8-1) -> 110 | C8: -51.6 | D8: =IF(C8="","",B8*C8) -> -5676 | E8: =IF(C8="","",B8^2) -> 12100 | F8: =IF(C8="","",$O$15*B8+$O$16) -> -50.871101 | G8: =IF(C8="","",(C8-F8)^2) -> 0.53129343 | H8: =IF(C8="","",C8-$O$11) -> 8.54 | I8: =IF(C8="","",H8^2) -> 72.9316 | J8: =IF(C8="","",B8-$O$10) -> -135 | K8: =IF(C8="","",J8^2) -> 18225 | L8: =IF(C8="","",J8*H8) -> -1152.9 | N8: Σx | O8: =SUMIF(C7:C36,"<>",B7:B36) -> 7350
A9: 3 | B9: =$B$2+$B$3*(A9-1) -> 120 | C9: -50.3 | D9: =IF(C9="","",B9*C9) -> -6036 | E9: =IF(C9="","",B9^2) -> 14400 | F9: =IF(C9="","",$O$15*B9+$O$16) -> -51.557686 | G9: =IF(C9="","",(C9-F9)^2) -> 1.5817749 | H9: =IF(C9="","",C9-$O$11) -> 9.84 | I9: =IF(C9="","",H9^2) -> 96.8256 | J9: =IF(C9="","",B9-$O$10) -> -125 | K9: =IF(C9="","",J9^2) -> 15625 | L9: =IF(C9="","",J9*H9) -> -1230 | N9: Σy | O9: =SUM(C7:C36) -> -1804.2
A10: 4 | B10: =$B$2+$B$3*(A10-1) -> 130 | C10: -51.4 | D10: =IF(C10="","",B10*C10) -> -6682 | E10: =IF(C10="","",B10^2) -> 16900 | F10: =IF(C10="","",$O$15*B10+$O$16) -> -52.244271 | G10: =IF(C10="","",(C10-F10)^2) -> 0.71279422 | H10: =IF(C10="","",C10-$O$11) -> 8.74 | I10: =IF(C10="","",H10^2) -> 76.3876 | J10: =IF(C10="","",B10-$O$10) -> -115 | K10: =IF(C10="","",J10^2) -> 13225 | L10: =IF(C10="","",J10*H10) -> -1005.1 | N10: Promedio x | O10: =O8/O7 -> 245
A11: 5 | B11: =$B$2+$B$3*(A11-1) -> 140 | C11: -53 | D11: =IF(C11="","",B11*C11) -> -7420 | E11: =IF(C11="","",B11^2) -> 19600 | F11: =IF(C11="","",$O$15*B11+$O$16) -> -52.930857 | G11: =IF(C11="","",(C11-F11)^2) -> 0.0047808226 | H11: =IF(C11="","",C11-$O$11) -> 7.14 | I11: =IF(C11="","",H11^2) -> 50.9796 | J11: =IF(C11="","",B11-$O$10) -> -105 | K11: =IF(C11="","",J11^2) -> 11025 | L11: =IF(C11="","",J11*H11) -> -749.7 | N11: Promedio y | O11: =O9/O7 -> -60.14
A12: 6 | B12: =$B$2+$B$3*(A12-1) -> 150 | C12: -54.4 | D12: =IF(C12="","",B12*C12) -> -8160 | E12: =IF(C12="","",B12^2) -> 22500 | F12: =IF(C12="","",$O$15*B12+$O$16) -> -53.617442 | G12: =IF(C12="","",(C12-F12)^2) -> 0.61239765 | H12: =IF(C12="","",C12-$O$11) -> 5.74 | I12: =IF(C12="","",H12^2) -> 32.9476 | J12: =IF(C12="","",B12-$O$10) -> -95 | K12: =IF(C12="","",J12^2) -> 9025 | L12: =IF(C12="","",J12*H12) -> -545.3 | N12: Σx² | O12: =SUM(E7:E36) -> 2025500
A13: 7 | B13: =$B$2+$B$3*(A13-1) -> 160 | C13: -52.4 | D13: =IF(C13="","",B13*C13) -> -8384 | E13: =IF(C13="","",B13^2) -> 25600 | F13: =IF(C13="","",$O$15*B13+$O$16) -> -54.304027 | G13: =IF(C13="","",(C13-F13)^2) -> 3.6253177 | H13: =IF(C13="","",C13-$O$11) -> 7.74 | I13: =IF(C13="","",H13^2) -> 59.9076 | J13: =IF(C13="","",B13-$O$10) -> -85 | K13: =IF(C13="","",J13^2) -> 7225 | L13: =IF(C13="","",J13*H13) -> -657.9 | N13: (Σx)² | O13: =O8^2 -> 54022500
A14: 8 | B14: =$B$2+$B$3*(A14-1) -> 170 | C14: -52.2 | D14: =IF(C14="","",B14*C14) -> -8874 | E14: =IF(C14="","",B14^2) -> 28900 | F14: =IF(C14="","",$O$15*B14+$O$16) -> -54.990612 | G14: =IF(C14="","",(C14-F14)^2) -> 7.7875142 | H14: =IF(C14="","",C14-$O$11) -> 7.94 | I14: =IF(C14="","",H14^2) -> 63.0436 | J14: =IF(C14="","",B14-$O$10) -> -75 | K14: =IF(C14="","",J14^2) -> 5625 | L14: =IF(C14="","",J14*H14) -> -595.5 | N14: Σxy | O14: =SUM(D7:D36) -> -457460
A15: 9 | B15: =$B$2+$B$3*(A15-1) -> 180 | C15: -54.1 | D15: =IF(C15="","",B15*C15) -> -9738 | E15: =IF(C15="","",B15^2) -> 32400 | F15: =IF(C15="","",$O$15*B15+$O$16) -> -55.677197 | G15: =IF(C15="","",(C15-F15)^2) -> 2.48755 | H15: =IF(C15="","",C15-$O$11) -> 6.04 | I15: =IF(C15="","",H15^2) -> 36.4816 | J15: =IF(C15="","",B15-$O$10) -> -65 | K15: =IF(C15="","",J15^2) -> 4225 | L15: =IF(C15="","",J15*H15) -> -392.6 | N15: m (pendiente) | O15: =(O7*O14-O8*O9)/(O7*O12-O13) -> -0.068658509
A16: 10 | B16: =$B$2+$B$3*(A16-1) -> 190 | C16: -58.8 | D16: =IF(C16="","",B16*C16) -> -11172 | E16: =IF(C16="","",B16^2) -> 36100 | F16: =IF(C16="","",$O$15*B16+$O$16) -> -56.363782 | G16: =IF(C16="","",(C16-F16)^2) -> 5.9351582 | H16: =IF(C16="","",C16-$O$11) -> 1.34 | I16: =IF(C16="","",H16^2) -> 1.7956 | J16: =IF(C16="","",B16-$O$10) -> -55 | K16: =IF(C16="","",J16^2) -> 3025 | L16: =IF(C16="","",J16*H16) -> -73.7 | N16: b (intersección) | O16: =(O9-O15*O8)/O7 -> -43.318665
A17: 11 | B17: =$B$2+$B$3*(A17-1) -> 200 | C17: -60.8 | D17: =IF(C17="","",B17*C17) -> -12160 | E17: =IF(C17="","",B17^2) -> 40000 | F17: =IF(C17="","",$O$15*B17+$O$16) -> -57.050367 | G17: =IF(C17="","",(C17-F17)^2) -> 14.059747 | H17: =IF(C17="","",C17-$O$11) -> -0.66 | I17: =IF(C17="","",H17^2) -> 0.4356 | J17: =IF(C17="","",B17-$O$10) -> -45 | K17: =IF(C17="","",J17^2) -> 2025 | L17: =IF(C17="","",J17*H17) -> 29.7 | N17: St | O17: =SUM(I7:I36) -> 1301.352
A18: 12 | B18: =$B$2+$B$3*(A18-1) -> 210 | C18: -55.8 | D18: =IF(C18="","",B18*C18) -> -11718 | E18: =IF(C18="","",B18^2) -> 44100 | F18: =IF(C18="","",$O$15*B18+$O$16) -> -57.736952 | G18: =IF(C18="","",(C18-F18)^2) -> 3.7517837 | H18: =IF(C18="","",C18-$O$11) -> 4.34 | I18: =IF(C18="","",H18^2) -> 18.8356 | J18: =IF(C18="","",B18-$O$10) -> -35 | K18: =IF(C18="","",J18^2) -> 1225 | L18: =IF(C18="","",J18*H18) -> -151.9 | N18: Sr | O18: =SUM(G7:G36) -> 241.88254
A19: 13 | B19: =$B$2+$B$3*(A19-1) -> 220 | C19: -57.9 | D19: =IF(C19="","",B19*C19) -> -12738 | E19: =IF(C19="","",B19^2) -> 48400 | F19: =IF(C19="","",$O$15*B19+$O$16) -> -58.423537 | G19: =IF(C19="","",(C19-F19)^2) -> 0.27409127 | H19: =IF(C19="","",C19-$O$11) -> 2.24 | I19: =IF(C19="","",H19^2) -> 5.0176 | J19: =IF(C19="","",B19-$O$10) -> -25 | K19: =IF(C19="","",J19^2) -> 625 | L19: =IF(C19="","",J19*H19) -> -56 | N19: R² | O19: =IFERROR((O17-O18)/O17,"") -> 0.81412981
A20: 14 | B20: =$B$2+$B$3*(A20-1) -> 230 | C20: -58.4 | D20: =IF(C20="","",B20*C20) -> -13432 | E20: =IF(C20="","",B20^2) -> 52900 | F20: =IF(C20="","",$O$15*B20+$O$16) -> -59.110122 | G20: =IF(C20="","",(C20-F20)^2) -> 0.50427376 | H20: =IF(C20="","",C20-$O$11) -> 1.74 | I20: =IF(C20="","",H20^2) -> 3.0276 | J20: =IF(C20="","",B20-$O$10) -> -15 | K20: =IF(C20="","",J20^2) -> 225 | L20: =IF(C20="","",J20*H20) -> -26.1 | N20: R | O20: =IFERROR(SUM(L7:L36)/SQRT(SUM(K7:K36)*SUM(I7:I36)),"") -> -0.90229142
A21: 15 | B21: =$B$2+$B$3*(A21-1) -> 240 | C21: -60.9 | D21: =IF(C21="","",B21*C21) -> -14616 | E21: =IF(C21="","",B21^2) -> 57600 | F21: =IF(C21="","",$O$15*B21+$O$16) -> -59.796707 | G21: =IF(C21="","",(C21-F21)^2) -> 1.2172544 | H21: =IF(C21="","",C21-$O$11) -> -0.76 | I21: =IF(C21="","",H21^2) -> 0.5776 | J21: =IF(C21="","",B21-$O$10) -> -5 | K21: =IF(C21="","",J21^2) -> 25 | L21: =IF(C21="","",J21*H21) -> 3.8
A22: 16 | B22: =$B$2+$B$3*(A22-1) -> 250 | C22: -59.3 | D22: =IF(C22="","",B22*C22) -> -14825 | E22: =IF(C22="","",B22^2) -> 62500 | F22: =IF(C22="","",$O$15*B22+$O$16) -> -60.483293 | G22: =IF(C22="","",(C22-F22)^2) -> 1.4001813 | H22: =IF(C22="","",C22-$O$11) -> 0.84 | I22: =IF(C22="","",H22^2) -> 0.7056 | J22: =IF(C22="","",B22-$O$10) -> 5 | K22: =IF(C22="","",J22^2) -> 25 | L22: =IF(C22="","",J22*H22) -> 4.2 | N22: Ecuación: | O22: ="y = "&TEXT(O15,"0.0000")&"x + "&TEXT(O16,"0.0000") -> y = 00.000x + -00.043
A23: 17 | B23: =$B$2+$B$3*(A23-1) -> 260 | C23: -65.1 | D23: =IF(C23="","",B23*C23) -> -16926 | E23: =IF(C23="","",B23^2) -> 67600 | F23: =IF(C23="","",$O$15*B23+$O$16) -> -61.169878 | G23: =IF(C23="","",(C23-F23)^2) -> 15.445862 | H23: =IF(C23="","",C23-$O$11) -> -4.96 | I23: =IF(C23="","",H23^2) -> 24.6016 | J23: =IF(C23="","",B23-$O$10) -> 15 | K23: =IF(C23="","",J23^2) -> 225 | L23: =IF(C23="","",J23*H23) -> -74.4
A24: 18 | B24: =$B$2+$B$3*(A24-1) -> 270 | C24: -65.4 | D24: =IF(C24="","",B24*C24) -> -17658 | E24: =IF(C24="","",B24^2) -> 72900 | F24: =IF(C24="","",$O$15*B24+$O$16) -> -61.856463 | G24: =IF(C24="","",(C24-F24)^2) -> 12.556656 | H24: =IF(C24="","",C24-$O$11) -> -5.26 | I24: =IF(C24="","",H24^2) -> 27.6676 | J24: =IF(C24="","",B24-$O$10) -> 25 | K24: =IF(C24="","",J24^2) -> 625 | L24: =IF(C24="","",J24*H24) -> -131.5
A25: 19 | B25: =$B$2+$B$3*(A25-1) -> 280 | C25: -70.6 | D25: =IF(C25="","",B25*C25) -> -19768 | E25: =IF(C25="","",B25^2) -> 78400 | F25: =IF(C25="","",$O$15*B25+$O$16) -> -62.543048 | G25: =IF(C25="","",(C25-F25)^2) -> 64.914478 | H25: =IF(C25="","",C25-$O$11) -> -10.46 | I25: =IF(C25="","",H25^2) -> 109.4116 | J25: =IF(C25="","",B25-$O$10) -> 35 | K25: =IF(C25="","",J25^2) -> 1225 | L25: =IF(C25="","",J25*H25) -> -366.1
A26: 20 | B26: =$B$2+$B$3*(A26-1) -> 290 | C26: -60.9 | D26: =IF(C26="","",B26*C26) -> -17661 | E26: =IF(C26="","",B26^2) -> 84100 | F26: =IF(C26="","",$O$15*B26+$O$16) -> -63.229633 | G26: =IF(C26="","",(C26-F26)^2) -> 5.4271896 | H26: =IF(C26="","",C26-$O$11) -> -0.76 | I26: =IF(C26="","",H26^2) -> 0.5776 | J26: =IF(C26="","",B26-$O$10) -> 45 | K26: =IF(C26="","",J26^2) -> 2025 | L26: =IF(C26="","",J26*H26) -> -34.2
A27: 21 | B27: =$B$2+$B$3*(A27-1) -> 300 | C27: -63.3 | D27: =IF(C27="","",B27*C27) -> -18990 | E27: =IF(C27="","",B27^2) -> 90000 | F27: =IF(C27="","",$O$15*B27+$O$16) -> -63.916218 | G27: =IF(C27="","",(C27-F27)^2) -> 0.37972465 | H27: =IF(C27="","",C27-$O$11) -> -3.16 | I27: =IF(C27="","",H27^2) -> 9.9856 | J27: =IF(C27="","",B27-$O$10) -> 55 | K27: =IF(C27="","",J27^2) -> 3025 | L27: =IF(C27="","",J27*H27) -> -173.8
A28: 22 | B28: =$B$2+$B$3*(A28-1) -> 310 | C28: -63.7 | D28: =IF(C28="","",B28*C28) -> -19747 | E28: =IF(C28="","",B28^2) -> 96100 | F28: =IF(C28="","",$O$15*B28+$O$16) -> -64.602803 | G28: =IF(C28="","",(C28-F28)^2) -> 0.81505346 | H28: =IF(C28="","",C28-$O$11) -> -3.56 | I28: =IF(C28="","",H28^2) -> 12.6736 | J28: =IF(C28="","",B28-$O$10) -> 65 | K28: =IF(C28="","",J28^2) -> 4225 | L28: =IF(C28="","",J28*H28) -> -231.4
A29: 23 | B29: =$B$2+$B$3*(A29-1) -> 320 | C29: -59.7 | D29: =IF(C29="","",B29*C29) -> -19104 | E29: =IF(C29="","",B29^2) -> 102400 | F29: =IF(C29="","",$O$15*B29+$O$16) -> -65.289388 | G29: =IF(C29="","",(C29-F29)^2) -> 31.241261 | H29: =IF(C29="","",C29-$O$11) -> 0.44 | I29: =IF(C29="","",H29^2) -> 0.1936 | J29: =IF(C29="","",B29-$O$10) -> 75 | K29: =IF(C29="","",J29^2) -> 5625 | L29: =IF(C29="","",J29*H29) -> 33
A30: 24 | B30: =$B$2+$B$3*(A30-1) -> 330 | C30: -68.6 | D30: =IF(C30="","",B30*C30) -> -22638 | E30: =IF(C30="","",B30^2) -> 108900 | F30: =IF(C30="","",$O$15*B30+$O$16) -> -65.975973 | G30: =IF(C30="","",(C30-F30)^2) -> 6.8855161 | H30: =IF(C30="","",C30-$O$11) -> -8.46 | I30: =IF(C30="","",H30^2) -> 71.5716 | J30: =IF(C30="","",B30-$O$10) -> 85 | K30: =IF(C30="","",J30^2) -> 7225 | L30: =IF(C30="","",J30*H30) -> -719.1
A31: 25 | B31: =$B$2+$B$3*(A31-1) -> 340 | C31: -61.4 | D31: =IF(C31="","",B31*C31) -> -20876 | E31: =IF(C31="","",B31^2) -> 115600 | F31: =IF(C31="","",$O$15*B31+$O$16) -> -66.662558 | G31: =IF(C31="","",(C31-F31)^2) -> 27.694521 | H31: =IF(C31="","",C31-$O$11) -> -1.26 | I31: =IF(C31="","",H31^2) -> 1.5876 | J31: =IF(C31="","",B31-$O$10) -> 95 | K31: =IF(C31="","",J31^2) -> 9025 | L31: =IF(C31="","",J31*H31) -> -119.7
A32: 26 | B32: =$B$2+$B$3*(A32-1) -> 350 | C32: -69.2 | D32: =IF(C32="","",B32*C32) -> -24220 | E32: =IF(C32="","",B32^2) -> 122500 | F32: =IF(C32="","",$O$15*B32+$O$16) -> -67.349143 | G32: =IF(C32="","",(C32-F32)^2) -> 3.4256698 | H32: =IF(C32="","",C32-$O$11) -> -9.06 | I32: =IF(C32="","",H32^2) -> 82.0836 | J32: =IF(C32="","",B32-$O$10) -> 105 | K32: =IF(C32="","",J32^2) -> 11025 | L32: =IF(C32="","",J32*H32) -> -951.3
A33: 27 | B33: =$B$2+$B$3*(A33-1) -> 360 | C33: -63.7 | D33: =IF(C33="","",B33*C33) -> -22932 | E33: =IF(C33="","",B33^2) -> 129600 | F33: =IF(C33="","",$O$15*B33+$O$16) -> -68.035729 | G33: =IF(C33="","",(C33-F33)^2) -> 18.798542 | H33: =IF(C33="","",C33-$O$11) -> -3.56 | I33: =IF(C33="","",H33^2) -> 12.6736 | J33: =IF(C33="","",B33-$O$10) -> 115 | K33: =IF(C33="","",J33^2) -> 13225 | L33: =IF(C33="","",J33*H33) -> -409.4
A34: 28 | B34: =$B$2+$B$3*(A34-1) -> 370 | C34: -71.8 | D34: =IF(C34="","",B34*C34) -> -26566 | E34: =IF(C34="","",B34^2) -> 136900 | F34: =IF(C34="","",$O$15*B34+$O$16) -> -68.722314 | G34: =IF(C34="","",(C34-F34)^2) -> 9.4721531 | H34: =IF(C34="","",C34-$O$11) -> -11.66 | I34: =IF(C34="","",H34^2) -> 135.9556 | J34: =IF(C34="","",B34-$O$10) -> 125 | K34: =IF(C34="","",J34^2) -> 15625 | L34: =IF(C34="","",J34*H34) -> -1457.5
... A36: 30 | B36: =$B$2+$B$3*(A36-1) -> 390 | C36: -70.5 | D36: =IF(C36="","",B36*C36) -> -27495 | E36: =IF(C36="","",B36^2) -> 152100 | F36: =IF(C36="","",$O$15*B36+$O$16) -> -70.095484 | G36: =IF(C36="","",(C36-F36)^2) -> 0.1636333 | H36: =IF(C36="","",C36-$O$11) -> -10.36 | I36: =IF(C36="","",H36^2) -> 107.3296 | J36: =IF(C36="","",B36-$O$10) -> 145 | K36: =IF(C36="","",J36^2) -> 21025 | L36: =IF(C36="","",J36*H36) -> -1502.2
C37: |

Sheet 20 puntos (m)
A1: Regresión lineal por mínimos cuadrados
A2: Valor inicial de x (m) | B2: 4
A3: Paso entre puntos (m) | B3: 1
A6: Observación | B6: Distancia x (m) | C6: y | D6: xy | E6: x^2 | F6: Y modelo | G6: (Y - Ymodelo)^2 | H6: y - yprom | I6: (Y-Yprom)^2 | J6: x - xprom | K6: (x-xprom)^2 | L6: (x-xprom)(y-yprom) | N6: Resumen | O6: Valor
A7: 1 | B7: =$B$2+$B$3*(A7-1) -> 4 | C7: -71.8 | D7: =IF(C7="","",B7*C7) -> -287.2 | E7: =IF(C7="","",B7^2) -> 16 | F7: =IF(C7="","",$O$15*B7+$O$16) -> -71.878571 | G7: =IF(C7="","",(C7-F7)^2) -> 0.0061734694 | H7: =IF(C7="","",C7-$O$11) -> 6.94 | I7: =IF(C7="","",H7^2) -> 48.1636 | J7: =IF(C7="","",B7-$O$10) -> -9.5 | K7: =IF(C7="","",J7^2) -> 90.25 | L7: =IF(C7="","",J7*H7) -> -65.93 | N7: n | O7: =COUNT(C7:C26) -> 20
A8: 2 | B8: =$B$2+$B$3*(A8-1) -> 5 | C8: -69 | D8: =IF(C8="","",B8*C8) -> -345 | E8: =IF(C8="","",B8^2) -> 25 | F8: =IF(C8="","",$O$15*B8+$O$16) -> -72.600827 | G8: =IF(C8="","",(C8-F8)^2) -> 12.965956 | H8: =IF(C8="","",C8-$O$11) -> 9.74 | I8: =IF(C8="","",H8^2) -> 94.8676 | J8: =IF(C8="","",B8-$O$10) -> -8.5 | K8: =IF(C8="","",J8^2) -> 72.25 | L8: =IF(C8="","",J8*H8) -> -82.79 | N8: Σx | O8: =SUMIF(C7:C26,"<>",B7:B26) -> 270
A9: 3 | B9: =$B$2+$B$3*(A9-1) -> 6 | C9: -65.5 | D9: =IF(C9="","",B9*C9) -> -393 | E9: =IF(C9="","",B9^2) -> 36 | F9: =IF(C9="","",$O$15*B9+$O$16) -> -73.323083 | G9: =IF(C9="","",(C9-F9)^2) -> 61.200623 | H9: =IF(C9="","",C9-$O$11) -> 13.24 | I9: =IF(C9="","",H9^2) -> 175.2976 | J9: =IF(C9="","",B9-$O$10) -> -7.5 | K9: =IF(C9="","",J9^2) -> 56.25 | L9: =IF(C9="","",J9*H9) -> -99.3 | N9: Σy | O9: =SUM(C7:C26) -> -1574.8
A10: 4 | B10: =$B$2+$B$3*(A10-1) -> 7 | C10: -68.7 | D10: =IF(C10="","",B10*C10) -> -480.9 | E10: =IF(C10="","",B10^2) -> 49 | F10: =IF(C10="","",$O$15*B10+$O$16) -> -74.045338 | G10: =IF(C10="","",(C10-F10)^2) -> 28.572642 | H10: =IF(C10="","",C10-$O$11) -> 10.04 | I10: =IF(C10="","",H10^2) -> 100.8016 | J10: =IF(C10="","",B10-$O$10) -> -6.5 | K10: =IF(C10="","",J10^2) -> 42.25 | L10: =IF(C10="","",J10*H10) -> -65.26 | N10: Promedio x | O10: =O8/O7 -> 13.5
A11: 5 | B11: =$B$2+$B$3*(A11-1) -> 8 | C11: -74.7 | D11: =IF(C11="","",B11*C11) -> -597.6 | E11: =IF(C11="","",B11^2) -> 64 | F11: =IF(C11="","",$O$15*B11+$O$16) -> -74.767594 | G11: =IF(C11="","",(C11-F11)^2) -> 0.0045689468 | H11: =IF(C11="","",C11-$O$11) -> 4.04 | I11: =IF(C11="","",H11^2) -> 16.3216 | J11: =IF(C11="","",B11-$O$10) -> -5.5 | K11: =IF(C11="","",J11^2) -> 30.25 | L11: =IF(C11="","",J11*H11) -> -22.22 | N11: Promedio y | O11: =O9/O7 -> -78.74
A12: 6 | B12: =$B$2+$B$3*(A12-1) -> 9 | C12: -85.6 | D12: =IF(C12="","",B12*C12) -> -770.4 | E12: =IF(C12="","",B12^2) -> 81 | F12: =IF(C12="","",$O$15*B12+$O$16) -> -75.48985 | G12: =IF(C12="","",(C12-F12)^2) -> 102.21514 | H12: =IF(C12="","",C12-$O$11) -> -6.86 | I12: =IF(C12="","",H12^2) -> 47.0596 | J12: =IF(C12="","",B12-$O$10) -> -4.5 | K12: =IF(C12="","",J12^2) -> 20.25 | L12: =IF(C12="","",J12*H12) -> 30.87 | N12: Σx² | O12: =SUM(E7:E26) -> 4310
A13: 7 | B13: =$B$2+$B$3*(A13-1) -> 10 | C13: -79.5 | D13: =IF(C13="","",B13*C13) -> -795 | E13: =IF(C13="","",B13^2) -> 100 | F13: =IF(C13="","",$O$15*B13+$O$16) -> -76.212105 | G13: =IF(C13="","",(C13-F13)^2) -> 10.810252 | H13: =IF(C13="","",C13-$O$11) -> -0.76 | I13: =IF(C13="","",H13^2) -> 0.5776 | J13: =IF(C13="","",B13-$O$10) -> -3.5 | K13: =IF(C13="","",J13^2) -> 12.25 | L13: =IF(C13="","",J13*H13) -> 2.66 | N13: (Σx)² | O13: =O8^2 -> 72900
A14: 8 | B14: =$B$2+$B$3*(A14-1) -> 11 | C14: -81.7 | D14: =IF(C14="","",B14*C14) -> -898.7 | E14: =IF(C14="","",B14^2) -> 121 | F14: =IF(C14="","",$O$15*B14+$O$16) -> -76.934361 | G14: =IF(C14="","",(C14-F14)^2) -> 22.711316 | H14: =IF(C14="","",C14-$O$11) -> -2.96 | I14: =IF(C14="","",H14^2) -> 8.7616 | J14: =IF(C14="","",B14-$O$10) -> -2.5 | K14: =IF(C14="","",J14^2) -> 6.25 | L14: =IF(C14="","",J14*H14) -> 7.4 | N14: Σxy | O14: =SUM(D7:D26) -> -21740.1
A15: 9 | B15: =$B$2+$B$3*(A15-1) -> 12 | C15: -78.9 | D15: =IF(C15="","",B15*C15) -> -946.8 | E15: =IF(C15="","",B15^2) -> 144 | F15: =IF(C15="","",$O$15*B15+$O$16) -> -77.656617 | G15: =IF(C15="","",(C15-F15)^2) -> 1.5460024 | H15: =IF(C15="","",C15-$O$11) -> -0.16 | I15: =IF(C15="","",H15^2) -> 0.0256 | J15: =IF(C15="","",B15-$O$10) -> -1.5 | K15: =IF(C15="","",J15^2) -> 2.25 | L15: =IF(C15="","",J15*H15) -> 0.24 | N15: m (pendiente) | O15: =(O7*O14-O8*O9)/(O7*O12-O13) -> -0.72225564
A16: 10 | B16: =$B$2+$B$3*(A16-1) -> 13 | C16: -76.9 | D16: =IF(C16="","",B16*C16) -> -999.7 | E16: =IF(C16="","",B16^2) -> 169 | F16: =IF(C16="","",$O$15*B16+$O$16) -> -78.378872 | G16: =IF(C16="","",(C16-F16)^2) -> 2.1870629 | H16: =IF(C16="","",C16-$O$11) -> 1.84 | I16: =IF(C16="","",H16^2) -> 3.3856 | J16: =IF(C16="","",B16-$O$10) -> -0.5 | K16: =IF(C16="","",J16^2) -> 0.25 | L16: =IF(C16="","",J16*H16) -> -0.92 | N16: b (intersección) | O16: =(O9-O15*O8)/O7 -> -68.989549
A17: 11 | B17: =$B$2+$B$3*(A17-1) -> 14 | C17: -80.4 | D17: =IF(C17="","",B17*C17) -> -1125.6 | E17: =IF(C17="","",B17^2) -> 196 | F17: =IF(C17="","",$O$15*B17+$O$16) -> -79.101128 | G17: =IF(C17="","",(C17-F17)^2) -> 1.6870689 | H17: =IF(C17="","",C17-$O$11) -> -1.66 | I17: =IF(C17="","",H17^2) -> 2.7556 | J17: =IF(C17="","",B17-$O$10) -> 0.5 | K17: =IF(C17="","",J17^2) -> 0.25 | L17: =IF(C17="","",J17*H17) -> -0.83 | N17: St | O17: =SUM(I7:I26) -> 702.948
A18: 12 | B18: =$B$2+$B$3*(A18-1) -> 15 | C18: -80.3 | D18: =IF(C18="","",B18*C18) -> -1204.5 | E18: =IF(C18="","",B18^2) -> 225 | F18: =IF(C18="","",$O$15*B18+$O$16) -> -79.823383 | G18: =IF(C18="","",(C18-F18)^2) -> 0.22716333 | H18: =IF(C18="","",C18-$O$11) -> -1.56 | I18: =IF(C18="","",H18^2) -> 2.4336 | J18: =IF(C18="","",B18-$O$10) -> 1.5 | K18: =IF(C18="","",J18^2) -> 2.25 | L18: =IF(C18="","",J18*H18) -> -2.34 | N18: Sr | O18: =SUM(G7:G26) -> 356.04862
A19: 13 | B19: =$B$2+$B$3*(A19-1) -> 16 | C19: -80 | D19: =IF(C19="","",B19*C19) -> -1280 | E19: =IF(C19="","",B19^2) -> 256 | F19: =IF(C19="","",$O$15*B19+$O$16) -> -80.545639 | G19: =IF(C19="","",(C19-F19)^2) -> 0.29772202 | H19: =IF(C19="","",C19-$O$11) -> -1.26 | I19: =IF(C19="","",H19^2) -> 1.5876 | J19: =IF(C19="","",B19-$O$10) -> 2.5 | K19: =IF(C19="","",J19^2) -> 6.25 | L19: =IF(C19="","",J19*H19) -> -3.15 | N19: R² | O19: =IFERROR((O17-O18)/O17,"") -> 0.49349224
A20: 14 | B20: =$B$2+$B$3*(A20-1) -> 17 | C20: -81.6 | D20: =IF(C20="","",B20*C20) -> -1387.2 | E20: =IF(C20="","",B20^2) -> 289 | F20: =IF(C20="","",$O$15*B20+$O$16) -> -81.267895 | G20: =IF(C20="","",(C20-F20)^2) -> 0.11029391 | H20: =IF(C20="","",C20-$O$11) -> -2.86 | I20: =IF(C20="","",H20^2) -> 8.1796 | J20: =IF(C20="","",B20-$O$10) -> 3.5 | K20: =IF(C20="","",J20^2) -> 12.25 | L20: =IF(C20="","",J20*H20) -> -10.01 | N20: R | O20: =IFERROR(SUM(L7:L26)/SQRT(SUM(K7:K26)*SUM(I7:I26)),"") -> -0.70249003
A21: 15 | B21: =$B$2+$B$3*(A21-1) -> 18 | C21: -84.3 | D21: =IF(C21="","",B21*C21) -> -1517.4 | E21: =IF(C21="","",B21^2) -> 324 | F21: =IF(C21="","",$O$15*B21+$O$16) -> -81.99015 | G21: =IF(C21="","",(C21-F21)^2) -> 5.3354053 | H21: =IF(C21="","",C21-$O$11) -> -5.56 | I21: =IF(C21="","",H21^2) -> 30.9136 | J21: =IF(C21="","",B21-$O$10) -> 4.5 | K21: =IF(C21="","",J21^2) -> 20.25 | L21: =IF(C21="","",J21*H21) -> -25.02
A22: 16 | B22: =$B$2+$B$3*(A22-1) -> 19 | C22: -88.1 | D22: =IF(C22="","",B22*C22) -> -1673.9 | E22: =IF(C22="","",B22^2) -> 361 | F22: =IF(C22="","",$O$15*B22+$O$16) -> -82.712406 | G22: =IF(C22="","",(C22-F22)^2) -> 29.026169 | H22: =IF(C22="","",C22-$O$11) -> -9.36 | I22: =IF(C22="","",H22^2) -> 87.6096 | J22: =IF(C22="","",B22-$O$10) -> 5.5 | K22: =IF(C22="","",J22^2) -> 30.25 | L22: =IF(C22="","",J22*H22) -> -51.48 | N22: Ecuación: | O22: ="y = "&TEXT(O15,"0.0000")&"x + "&TEXT(O16,"0.0000") -> y = -00.001x + -00.069
A23: 17 | B23: =$B$2+$B$3*(A23-1) -> 20 | C23: -86.7 | D23: =IF(C23="","",B23*C23) -> -1734 | E23: =IF(C23="","",B23^2) -> 400 | F23: =IF(C23="","",$O$15*B23+$O$16) -> -83.434662 | G23: =IF(C23="","",(C23-F23)^2) -> 10.662435 | H23: =IF(C23="","",C23-$O$11) -> -7.96 | I23: =IF(C23="","",H23^2) -> 63.3616 | J23: =IF(C23="","",B23-$O$10) -> 6.5 | K23: =IF(C23="","",J23^2) -> 42.25 | L23: =IF(C23="","",J23*H23) -> -51.74
A24: 18 | B24: =$B$2+$B$3*(A24-1) -> 21 | C24: -81.5 | D24: =IF(C24="","",B24*C24) -> -1711.5 | E24: =IF(C24="","",B24^2) -> 441 | F24: =IF(C24="","",$O$15*B24+$O$16) -> -84.156917 | G24: =IF(C24="","",(C24-F24)^2) -> 7.0592095 | H24: =IF(C24="","",C24-$O$11) -> -2.76 | I24: =IF(C24="","",H24^2) -> 7.6176 | J24: =IF(C24="","",B24-$O$10) -> 7.5 | K24: =IF(C24="","",J24^2) -> 56.25 | L24: =IF(C24="","",J24*H24) -> -20.7
A25: 19 | B25: =$B$2+$B$3*(A25-1) -> 22 | C25: -79.1 | D25: =IF(C25="","",B25*C25) -> -1740.2 | E25: =IF(C25="","",B25^2) -> 484 | F25: =IF(C25="","",$O$15*B25+$O$16) -> -84.879173 | G25: =IF(C25="","",(C25-F25)^2) -> 33.39884 | H25: =IF(C25="","",C25-$O$11) -> -0.36 | I25: =IF(C25="","",H25^2) -> 0.1296 | J25: =IF(C25="","",B25-$O$10) -> 8.5 | K25: =IF(C25="","",J25^2) -> 72.25 | L25: =IF(C25="","",J25*H25) -> -3.06
A26: 20 | B26: =$B$2+$B$3*(A26-1) -> 23 | C26: -80.5 | D26: =IF(C26="","",B26*C26) -> -1851.5 | E26: =IF(C26="","",B26^2) -> 529 | F26: =IF(C26="","",$O$15*B26+$O$16) -> -85.601429 | G26: =IF(C26="","",(C26-F26)^2) -> 26.024573 | H26: =IF(C26="","",C26-$O$11) -> -1.76 | I26: =IF(C26="","",H26^2) -> 3.0976 | J26: =IF(C26="","",B26-$O$10) -> 9.5 | K26: =IF(C26="","",J26^2) -> 90.25 | L26: =IF(C26="","",J26*H26) -> -16.72

Sheet Todos juntos (m)
A1: Regresión lineal por mínimos cuadrados - todos los puntos juntos
A2: Unidad de x en esta hoja | B2: metros
A3: Divisor cm → m | B3: 100
A6: Observación | B6: Distancia x (m) | C6: y | D6: xy | E6: x^2 | F6: Y modelo | G6: (Y - Ymodelo)^2 | H6: y - yprom | I6: (Y-Yprom)^2 | J6: x - xprom | K6: (x-xprom)^2 | L6: (x-xprom)(y-yprom) | M6: Origen | N6: Resumen | O6: Valor
A7: 1 | B7: ='30 puntos (cm)'!B7/$B$3 -> 1 | C7: =IF('30 puntos (cm)'!C7="","",'30 puntos (cm)'!C7) -> -49.9 | D7: =IF(C7="","",B7*C7) -> -49.9 | E7: =IF(C7="","",B7^2) -> 1 | F7: =IF(C7="","",$O$15*B7+$O$16) -> -59.124269 | G7: =IF(C7="","",(C7-F7)^2) -> 85.087143 | H7: =IF(C7="","",C7-$O$11) -> 17.68 | I7: =IF(C7="","",H7^2) -> 312.5824 | J7: =IF(C7="","",B7-$O$10) -> -5.87 | K7: =IF(C7="","",J7^2) -> 34.4569 | L7: =IF(C7="","",J7*H7) -> -103.7816 | M7: Hoja cm | N7: n | O7: =COUNT(C7:C56) -> 50
A8: 2 | B8: ='30 puntos (cm)'!B8/$B$3 -> 1.1 | C8: =IF('30 puntos (cm)'!C8="","",'30 puntos (cm)'!C8) -> -51.6 | D8: =IF(C8="","",B8*C8) -> -56.76 | E8: =IF(C8="","",B8^2) -> 1.21 | F8: =IF(C8="","",$O$15*B8+$O$16) -> -59.268319 | G8: =IF(C8="","",(C8-F8)^2) -> 58.803119 | H8: =IF(C8="","",C8-$O$11) -> 15.98 | I8: =IF(C8="","",H8^2) -> 255.3604 | J8: =IF(C8="","",B8-$O$10) -> -5.77 | K8: =IF(C8="","",J8^2) -> 33.2929 | L8: =IF(C8="","",J8*H8) -> -92.2046 | M8: Hoja cm | N8: Σx | O8: =SUMIF(C7:C56,"<>",B7:B56) -> 343.5
A9: 3 | B9: ='30 puntos (cm)'!B9/$B$3 -> 1.2 | C9: =IF('30 puntos (cm)'!C9="","",'30 puntos (cm)'!C9) -> -50.3 | D9: =IF(C9="","",B9*C9) -> -60.36 | E9: =IF(C9="","",B9^2) -> 1.44 | F9: =IF(C9="","",$O$15*B9+$O$16) -> -59.412369 | G9: =IF(C9="","",(C9-F9)^2) -> 83.03527 | H9: =IF(C9="","",C9-$O$11) -> 17.28 | I9: =IF(C9="","",H9^2) -> 298.5984 | J9: =IF(C9="","",B9-$O$10) -> -5.67 | K9: =IF(C9="","",J9^2) -> 32.1489 | L9: =IF(C9="","",J9*H9) -> -97.9776 | M9: Hoja cm | N9: Σy | O9: =SUM(C7:C56) -> -3379
A10: 4 | B10: ='30 puntos (cm)'!B10/$B$3 -> 1.3 | C10: =IF('30 puntos (cm)'!C10="","",'30 puntos (cm)'!C10) -> -51.4 | D10: =IF(C10="","",B10*C10) -> -66.82 | E10: =IF(C10="","",B10^2) -> 1.69 | F10: =IF(C10="","",$O$15*B10+$O$16) -> -59.556419 | G10: =IF(C10="","",(C10-F10)^2) -> 66.527171 | H10: =IF(C10="","",C10-$O$11) -> 16.18 | I10: =IF(C10="","",H10^2) -> 261.7924 | J10: =IF(C10="","",B10-$O$10) -> -5.57 | K10: =IF(C10="","",J10^2) -> 31.0249 | L10: =IF(C10="","",J10*H10) -> -90.1226 | M10: Hoja cm | N10: Promedio x | O10: =O8/O7 -> 6.87
A11: 5 | B11: ='30 puntos (cm)'!B11/$B$3 -> 1.4 | C11: =IF('30 puntos (cm)'!C11="","",'30 puntos (cm)'!C11) -> -53 | D11: =IF(C11="","",B11*C11) -> -74.2 | E11: =IF(C11="","",B11^2) -> 1.96 | F11: =IF(C11="","",$O$15*B11+$O$16) -> -59.700469 | G11: =IF(C11="","",(C11-F11)^2) -> 44.896284 | H11: =IF(C11="","",C11-$O$11) -> 14.58 | I11: =IF(C11="","",H11^2) -> 212.5764 | J11: =IF(C11="","",B11-$O$10) -> -5.47 | K11: =IF(C11="","",J11^2) -> 29.9209 | L11: =IF(C11="","",J11*H11) -> -79.7526 | M11: Hoja cm | N11: Promedio y | O11: =O9/O7 -> -67.58
A12: 6 | B12: ='30 puntos (cm)'!B12/$B$3 -> 1.5 | C12: =IF('30 puntos (cm)'!C12="","",'30 puntos (cm)'!C12) -> -54.4 | D12: =IF(C12="","",B12*C12) -> -81.6 | E12: =IF(C12="","",B12^2) -> 2.25 | F12: =IF(C12="","",$O$15*B12+$O$16) -> -59.844519 | G12: =IF(C12="","",(C12-F12)^2) -> 29.642786 | H12: =IF(C12="","",C12-$O$11) -> 13.18 | I12: =IF(C12="","",H12^2) -> 173.7124 | J12: =IF(C12="","",B12-$O$10) -> -5.37 | K12: =IF(C12="","",J12^2) -> 28.8369 | L12: =IF(C12="","",J12*H12) -> -70.7766 | M12: Hoja cm | N12: Σx² | O12: =SUM(E7:E56) -> 4512.55
A13: 7 | B13: ='30 puntos (cm)'!B13/$B$3 -> 1.6 | C13: =IF('30 puntos (cm)'!C13="","",'30 puntos (cm)'!C13) -> -52.4 | D13: =IF(C13="","",B13*C13) -> -83.84 | E13: =IF(C13="","",B13^2) -> 2.56 | F13: =IF(C13="","",$O$15*B13+$O$16) -> -59.988569 | G13: =IF(C13="","",(C13-F13)^2) -> 57.586376 | H13: =IF(C13="","",C13-$O$11) -> 15.18 | I13: =IF(C13="","",H13^2) -> 230.4324 | J13: =IF(C13="","",B13-$O$10) -> -5.27 | K13: =IF(C13="","",J13^2) -> 27.7729 | L13: =IF(C13="","",J13*H13) -> -79.9986 | M13: Hoja cm | N13: (Σx)² | O13: =O8^2 -> 117992.25
A14: 8 | B14: ='30 puntos (cm)'!B14/$B$3 -> 1.7 | C14: =IF('30 puntos (cm)'!C14="","",'30 puntos (cm)'!C14) -> -52.2 | D14: =IF(C14="","",B14*C14) -> -88.74 | E14: =IF(C14="","",B14^2) -> 2.89 | F14: =IF(C14="","",$O$15*B14+$O$16) -> -60.132619 | G14: =IF(C14="","",(C14-F14)^2) -> 62.92644 | H14: =IF(C14="","",C14-$O$11) -> 15.38 | I14: =IF(C14="","",H14^2) -> 236.5444 | J14: =IF(C14="","",B14-$O$10) -> -5.17 | K14: =IF(C14="","",J14^2) -> 26.7289 | L14: =IF(C14="","",J14*H14) -> -79.5146 | M14: Hoja cm | N14: Σxy | O14: =SUM(D7:D56) -> -26314.7
A15: 9 | B15: ='30 puntos (cm)'!B15/$B$3 -> 1.8 | C15: =IF('30 puntos (cm)'!C15="","",'30 puntos (cm)'!C15) -> -54.1 | D15: =IF(C15="","",B15*C15) -> -97.38 | E15: =IF(C15="","",B15^2) -> 3.24 | F15: =IF(C15="","",$O$15*B15+$O$16) -> -60.276669 | G15: =IF(C15="","",(C15-F15)^2) -> 38.151236 | H15: =IF(C15="","",C15-$O$11) -> 13.48 | I15: =IF(C15="","",H15^2) -> 181.7104 | J15: =IF(C15="","",B15-$O$10) -> -5.07 | K15: =IF(C15="","",J15^2) -> 25.7049 | L15: =IF(C15="","",J15*H15) -> -68.3436 | M15: Hoja cm | N15: m (pendiente) | O15: =(O7*O14-O8*O9)/(O7*O12-O13) -> -1.4404993
A16: 10 | B16: ='30 puntos (cm)'!B16/$B$3 -> 1.9 | C16: =IF('30 puntos (cm)'!C16="","",'30 puntos (cm)'!C16) -> -58.8 | D16: =IF(C16="","",B16*C16) -> -111.72 | E16: =IF(C16="","",B16^2) -> 3.61 | F16: =IF(C16="","",$O$15*B16+$O$16) -> -60.420719 | G16: =IF(C16="","",(C16-F16)^2) -> 2.6267287 | H16: =IF(C16="","",C16-$O$11) -> 8.78 | I16: =IF(C16="","",H16^2) -> 77.0884 | J16: =IF(C16="","",B16-$O$10) -> -4.97 | K16: =IF(C16="","",J16^2) -> 24.7009 | L16: =IF(C16="","",J16*H16) -> -43.6366 | M16: Hoja cm | N16: b (intersección) | O16: =(O9-O15*O8)/O7 -> -57.68377
A17: 11 | B17: ='30 puntos (cm)'!B17/$B$3 -> 2 | C17: =IF('30 puntos (cm)'!C17="","",'30 puntos (cm)'!C17) -> -60.8 | D17: =IF(C17="","",B17*C17) -> -121.6 | E17: =IF(C17="","",B17^2) -> 4 | F17: =IF(C17="","",$O$15*B17+$O$16) -> -60.564769 | G17: =IF(C17="","",(C17-F17)^2) -> 0.055333853 | H17: =IF(C17="","",C17-$O$11) -> 6.78 | I17: =IF(C17="","",H17^2) -> 45.9684 | J17: =IF(C17="","",B17-$O$10) -> -4.87 | K17: =IF(C17="","",J17^2) -> 23.7169 | L17: =IF(C17="","",J17*H17) -> -33.0186 | M17: Hoja cm | N17: St | O17: =SUM(I7:I56) -> 6155.82
A18: 12 | B18: ='30 puntos (cm)'!B18/$B$3 -> 2.1 | C18: =IF('30 puntos (cm)'!C18="","",'30 puntos (cm)'!C18) -> -55.8 | D18: =IF(C18="","",B18*C18) -> -117.18 | E18: =IF(C18="","",B18^2) -> 4.41 | F18: =IF(C18="","",$O$15*B18+$O$16) -> -60.708818 | G18: =IF(C18="","",(C18-F18)^2) -> 24.096498 | H18: =IF(C18="","",C18-$O$11) -> 11.78 | I18: =IF(C18="","",H18^2) -> 138.7684 | J18: =IF(C18="","",B18-$O$10) -> -4.77 | K18: =IF(C18="","",J18^2) -> 22.7529 | L18: =IF(C18="","",J18*H18) -> -56.1906 | M18: Hoja cm | N18: Sr | O18: =SUM(G7:G56) -> 1688.875
A19: 13 | B19: ='30 puntos (cm)'!B19/$B$3 -> 2.2 | C19: =IF('30 puntos (cm)'!C19="","",'30 puntos (cm)'!C19) -> -57.9 | D19: =IF(C19="","",B19*C19) -> -127.38 | E19: =IF(C19="","",B19^2) -> 4.84 | F19: =IF(C19="","",$O$15*B19+$O$16) -> -60.852868 | G19: =IF(C19="","",(C19-F19)^2) -> 8.7194316 | H19: =IF(C19="","",C19-$O$11) -> 9.68 | I19: =IF(C19="","",H19^2) -> 93.7024 | J19: =IF(C19="","",B19-$O$10) -> -4.67 | K19: =IF(C19="","",J19^2) -> 21.8089 | L19: =IF(C19="","",J19*H19) -> -45.2056 | M19: Hoja cm | N19: R² | O19: =IFERROR((O17-O18)/O17,"") -> 0.72564582
A20: 14 | B20: ='30 puntos (cm)'!B20/$B$3 -> 2.3 | C20: =IF('30 puntos (cm)'!C20="","",'30 puntos (cm)'!C20) -> -58.4 | D20: =IF(C20="","",B20*C20) -> -134.32 | E20: =IF(C20="","",B20^2) -> 5.29 | F20: =IF(C20="","",$O$15*B20+$O$16) -> -60.996918 | G20: =IF(C20="","",(C20-F20)^2) -> 6.7439846 | H20: =IF(C20="","",C20-$O$11) -> 9.18 | I20: =IF(C20="","",H20^2) -> 84.2724 | J20: =IF(C20="","",B20-$O$10) -> -4.57 | K20: =IF(C20="","",J20^2) -> 20.8849 | L20: =IF(C20="","",J20*H20) -> -41.9526 | M20: Hoja cm | N20: R | O20: =IFERROR(SUM(L7:L56)/SQRT(SUM(K7:K56)*SUM(I7:I56)),"") -> -0.85184847
A21: 15 | B21: ='30 puntos (cm)'!B21/$B$3 -> 2.4 | C21: =IF('30 puntos (cm)'!C21="","",'30 puntos (cm)'!C21) -> -60.9 | D21: =IF(C21="","",B21*C21) -> -146.16 | E21: =IF(C21="","",B21^2) -> 5.76 | F21: =IF(C21="","",$O$15*B21+$O$16) -> -61.140968 | G21: =IF(C21="","",(C21-F21)^2) -> 0.058065685 | H21: =IF(C21="","",C21-$O$11) -> 6.68 | I21: =IF(C21="","",H21^2) -> 44.6224 | J21: =IF(C21="","",B21-$O$10) -> -4.47 | K21: =IF(C21="","",J21^2) -> 19.9809 | L21: =IF(C21="","",J21*H21) -> -29.8596 | M21: Hoja cm
A22: 16 | B22: ='30 puntos (cm)'!B22/$B$3 -> 2.5 | C22: =IF('30 puntos (cm)'!C22="","",'30 puntos (cm)'!C22) -> -59.3 | D22: =IF(C22="","",B22*C22) -> -148.25 | E22: =IF(C22="","",B22^2) -> 6.25 | F22: =IF(C22="","",$O$15*B22+$O$16) -> -61.285018 | G22: =IF(C22="","",(C22-F22)^2) -> 3.9402971 | H22: =IF(C22="","",C22-$O$11) -> 8.28 | I22: =IF(C22="","",H22^2) -> 68.5584 | J22: =IF(C22="","",B22-$O$10) -> -4.37 | K22: =IF(C22="","",J22^2) -> 19.0969 | L22: =IF(C22="","",J22*H22) -> -36.1836 | M22: Hoja cm | N22: Ecuación: | O22: ="y = "&TEXT(O15,"0.0000")&"x + "&TEXT(O16,"0.0000") -> y = -00.001x + -00.058
A23: 17 | B23: ='30 puntos (cm)'!B23/$B$3 -> 2.6 | C23: =IF('30 puntos (cm)'!C23="","",'30 puntos (cm)'!C23) -> -65.1 | D23: =IF(C23="","",B23*C23) -> -169.26 | E23: =IF(C23="","",B23^2) -> 6.76 | F23: =IF(C23="","",$O$15*B23+$O$16) -> -61.429068 | G23: =IF(C23="","",(C23-F23)^2) -> 13.475741 | H23: =IF(C23="","",C23-$O$11) -> 2.48 | I23: =IF(C23="","",H23^2) -> 6.1504 | J23: =IF(C23="","",B23-$O$10) -> -4.27 | K23: =IF(C23="","",J23^2) -> 18.2329 | L23: =IF(C23="","",J23*H23) -> -10.5896 | M23: Hoja cm
A24: 18 | B24: ='30 puntos (cm)'!B24/$B$3 -> 2.7 | C24: =IF('30 puntos (cm)'!C24="","",'30 puntos (cm)'!C24) -> -65.4 | D24: =IF(C24="","",B24*C24) -> -176.58 | E24: =IF(C24="","",B24^2) -> 7.29 | F24: =IF(C24="","",$O$15*B24+$O$16) -> -61.573118 | G24: =IF(C24="","",(C24-F24)^2) -> 14.645026 | H24: =IF(C24="","",C24-$O$11) -> 2.18 | I24: =IF(C24="","",H24^2) -> 4.7524 | J24: =IF(C24="","",B24-$O$10) -> -4.17 | K24: =IF(C24="","",J24^2) -> 17.3889 | L24: =IF(C24="","",J24*H24) -> -9.0906 | M24: Hoja cm
A25: 19 | B25: ='30 puntos (cm)'!B25/$B$3 -> 2.8 | C25: =IF('30 puntos (cm)'!C25="","",'30 puntos (cm)'!C25) -> -70.6 | D25: =IF(C25="","",B25*C25) -> -197.68 | E25: =IF(C25="","",B25^2) -> 7.84 | F25: =IF(C25="","",$O$15*B25+$O$16) -> -61.717168 | G25: =IF(C25="","",(C25-F25)^2) -> 78.904705 | H25: =IF(C25="","",C25-$O$11) -> -3.02 | I25: =IF(C25="","",H25^2) -> 9.1204 | J25: =IF(C25="","",B25-$O$10) -> -4.07 | K25: =IF(C25="","",J25^2) -> 16.5649 | L25: =IF(C25="","",J25*H25) -> 12.2914 | M25: Hoja cm
A26: 20 | B26: ='30 puntos (cm)'!B26/$B$3 -> 2.9 | C26: =IF('30 puntos (cm)'!C26="","",'30 puntos (cm)'!C26) -> -60.9 | D26: =IF(C26="","",B26*C26) -> -176.61 | E26: =IF(C26="","",B26^2) -> 8.41 | F26: =IF(C26="","",$O$15*B26+$O$16) -> -61.861218 | G26: =IF(C26="","",(C26-F26)^2) -> 0.92393978 | H26: =IF(C26="","",C26-$O$11) -> 6.68 | I26: =IF(C26="","",H26^2) -> 44.6224 | J26: =IF(C26="","",B26-$O$10) -> -3.97 | K26: =IF(C26="","",J26^2) -> 15.7609 | L26: =IF(C26="","",J26*H26) -> -26.5196 | M26: Hoja cm
A27: 21 | B27: ='30 puntos (cm)'!B27/$B$3 -> 3 | C27: =IF('30 puntos (cm)'!C27="","",'30 puntos (cm)'!C27) -> -63.3 | D27: =IF(C27="","",B27*C27) -> -189.9 | E27: =IF(C27="","",B27^2) -> 9 | F27: =IF(C27="","",$O$15*B27+$O$16) -> -62.005268 | G27: =IF(C27="","",(C27-F27)^2) -> 1.6763315 | H27: =IF(C27="","",C27-$O$11) -> 4.28 | I27: =IF(C27="","",H27^2) -> 18.3184 | J27: =IF(C27="","",B27-$O$10) -> -3.87 | K27: =IF(C27="","",J27^2) -> 14.9769 | L27: =IF(C27="","",J27*H27) -> -16.5636 | M27: Hoja cm
A28: 22 | B28: ='30 puntos (cm)'!B28/$B$3 -> 3.1 | C28: =IF('30 puntos (cm)'!C28="","",'30 puntos (cm)'!C28) -> -63.7 | D28: =IF(C28="","",B28*C28) -> -197.47 | E28: =IF(C28="","",B28^2) -> 9.61 | F28: =IF(C28="","",$O$15*B28+$O$16) -> -62.149318 | G28: =IF(C28="","",(C28-F28)^2) -> 2.4046155 | H28: =IF(C28="","",C28-$O$11) -> 3.88 | I28: =IF(C28="","",H28^2) -> 15.0544 | J28: =IF(C28="","",B28-$O$10) -> -3.77 | K28: =IF(C28="","",J28^2) -> 14.2129 | L28: =IF(C28="","",J28*H28) -> -14.6276 | M28: Hoja cm
A29: 23 | B29: ='30 puntos (cm)'!B29/$B$3 -> 3.2 | C29: =IF('30 puntos (cm)'!C29="","",'30 puntos (cm)'!C29) -> -59.7 | D29: =IF(C29="","",B29*C29) -> -191.04 | E29: =IF(C29="","",B29^2) -> 10.24 | F29: =IF(C29="","",$O$15*B29+$O$16) -> -62.293368 | G29: =IF(C29="","",(C29-F29)^2) -> 6.7255558 | H29: =IF(C29="","",C29-$O$11) -> 7.88 | I29: =IF(C29="","",H29^2) -> 62.0944 | J29: =IF(C29="","",B29-$O$10) -> -3.67 | K29: =IF(C29="","",J29^2) -> 13.4689 | L29: =IF(C29="","",J29*H29) -> -28.9196 | M29: Hoja cm
A30: 24 | B30: ='30 puntos (cm)'!B30/$B$3 -> 3.3 | C30: =IF('30 puntos (cm)'!C30="","",'30 puntos (cm)'!C30) -> -68.6 | D30: =IF(C30="","",B30*C30) -> -226.38 | E30: =IF(C30="","",B30^2) -> 10.89 | F30: =IF(C30="","",$O$15*B30+$O$16) -> -62.437418 | G30: =IF(C30="","",(C30-F30)^2) -> 37.977422 | H30: =IF(C30="","",C30-$O$11) -> -1.02 | I30: =IF(C30="","",H30^2) -> 1.0404 | J30: =IF(C30="","",B30-$O$10) -> -3.57 | K30: =IF(C30="","",J30^2) -> 12.7449 | L30: =IF(C30="","",J30*H30) -> 3.6414 | M30: Hoja cm
A31: 25 | B31: ='30 puntos (cm)'!B31/$B$3 -> 3.4 | C31: =IF('30 puntos (cm)'!C31="","",'30 puntos (cm)'!C31) -> -61.4 | D31: =IF(C31="","",B31*C31) -> -208.76 | E31: =IF(C31="","",B31^2) -> 11.56 | F31: =IF(C31="","",$O$15*B31+$O$16) -> -62.581468 | G31: =IF(C31="","",(C31-F31)^2) -> 1.3958655 | H31: =IF(C31="","",C31-$O$11) -> 6.18 | I31: =IF(C31="","",H31^2) -> 38.1924 | J31: =IF(C31="","",B31-$O$10) -> -3.47 | K31: =IF(C31="","",J31^2) -> 12.0409 | L31: =IF(C31="","",J31*H31) -> -21.4446 | M31: Hoja cm
A32: 26 | B32: ='30 puntos (cm)'!B32/$B$3 -> 3.5 | C32: =IF('30 puntos (cm)'!C32="","",'30 puntos (cm)'!C32) -> -69.2 | D32: =IF(C32="","",B32*C32) -> -242.2 | E32: =IF(C32="","",B32^2) -> 12.25 | F32: =IF(C32="","",$O$15*B32+$O$16) -> -62.725517 | G32: =IF(C32="","",(C32-F32)^2) -> 41.918925 | H32: =IF(C32="","",C32-$O$11) -> -1.62 | I32: =IF(C32="","",H32^2) -> 2.6244 | J32: =IF(C32="","",B32-$O$10) -> -3.37 | K32: =IF(C32="","",J32^2) -> 11.3569 | L32: =IF(C32="","",J32*H32) -> 5.4594 | M32: Hoja cm
A33: 27 | B33: ='30 puntos (cm)'!B33/$B$3 -> 3.6 | C33: =IF('30 puntos (cm)'!C33="","",'30 puntos (cm)'!C33) -> -63.7 | D33: =IF(C33="","",B33*C33) -> -229.32 | E33: =IF(C33="","",B33^2) -> 12.96 | F33: =IF(C33="","",$O$15*B33+$O$16) -> -62.869567 | G33: =IF(C33="","",(C33-F33)^2) -> 0.68961837 | H33: =IF(C33="","",C33-$O$11) -> 3.88 | I33: =IF(C33="","",H33^2) -> 15.0544 | J33: =IF(C33="","",B33-$O$10) -> -3.27 | K33: =IF(C33="","",J33^2) -> 10.6929 | L33: =IF(C33="","",J33*H33) -> -12.6876 | M33: Hoja cm
A34: 28 | B34: ='30 puntos (cm)'!B34/$B$3 -> 3.7 | C34: =IF('30 puntos (cm)'!C34="","",'30 puntos (cm)'!C34) -> -71.8 | D34: =IF(C34="","",B34*C34) -> -265.66 | E34: =IF(C34="","",B34^2) -> 13.69 | F34: =IF(C34="","",$O$15*B34+$O$16) -> -63.013617 | G34: =IF(C34="","",(C34-F34)^2) -> 77.200521 | H34: =IF(C34="","",C34-$O$11) -> -4.22 | I34: =IF(C34="","",H34^2) -> 17.8084 | J34: =IF(C34="","",B34-$O$10) -> -3.17 | K34: =IF(C34="","",J34^2) -> 10.0489 | L34: =IF(C34="","",J34*H34) -> 13.3774 | M34: Hoja cm
... A36: 30 | B36: ='30 puntos (cm)'!B36/$B$3 -> 3.9 | C36: =IF('30 puntos (cm)'!C36="","",'30 puntos (cm)'!C36) -> -70.5 | D36: =IF(C36="","",B36*C36) -> -274.95 | E36: =IF(C36="","",B36^2) -> 15.21 | F36: =IF(C36="","",$O$15*B36+$O$16) -> -63.301717 | G36: =IF(C36="","",(C36-F36)^2) -> 51.815276 | H36: =IF(C36="","",C36-$O$11) -> -2.92 | I36: =IF(C36="","",H36^2) -> 8.5264 | J36: =IF(C36="","",B36-$O$10) -> -2.97 | K36: =IF(C36="","",J36^2) -> 8.8209 | L36: =IF(C36="","",J36*H36) -> 8.6724 | M36: Hoja cm
A37: 31 | B37: ='20 puntos (m)'!B7 -> 4 | C37: =IF('20 puntos (m)'!C7="","",'20 puntos (m)'!C7) -> -71.8 | D37: =IF(C37="","",B37*C37) -> -287.2 | E37: =IF(C37="","",B37^2) -> 16 | F37: =IF(C37="","",$O$15*B37+$O$16) -> -63.445767 | G37: =IF(C37="","",(C37-F37)^2) -> 69.793208 | H37: =IF(C37="","",C37-$O$11) -> -4.22 | I37: =IF(C37="","",H37^2) -> 17.8084 | J37: =IF(C37="","",B37-$O$10) -> -2.87 | K37: =IF(C37="","",J37^2) -> 8.2369 | L37: =IF(C37="","",J37*H37) -> 12.1114 | M37: Hoja m
A38: 32 | B38: ='20 puntos (m)'!B8 -> 5 | C38: =IF('20 puntos (m)'!C8="","",'20 puntos (m)'!C8) -> -69 | D38: =IF(C38="","",B38*C38) -> -345 | E38: =IF(C38="","",B38^2) -> 25 | F38: =IF(C38="","",$O$15*B38+$O$16) -> -64.886266 | G38: =IF(C38="","",(C38-F38)^2) -> 16.922805 | H38: =IF(C38="","",C38-$O$11) -> -1.42 | I38: =IF(C38="","",H38^2) -> 2.0164 | J38: =IF(C38="","",B38-$O$10) -> -1.87 | K38: =IF(C38="","",J38^2) -> 3.4969 | L38: =IF(C38="","",J38*H38) -> 2.6554 | M38: Hoja m
A39: 33 | B39: ='20 puntos (m)'!B9 -> 6 | C39: =IF('20 puntos (m)'!C9="","",'20 puntos (m)'!C9) -> -65.5 | D39: =IF(C39="","",B39*C39) -> -393 | E39: =IF(C39="","",B39^2) -> 36 | F39: =IF(C39="","",$O$15*B39+$O$16) -> -66.326766 | G39: =IF(C39="","",(C39-F39)^2) -> 0.6835414 | H39: =IF(C39="","",C39-$O$11) -> 2.08 | I39: =IF(C39="","",H39^2) -> 4.3264 | J39: =IF(C39="","",B39-$O$10) -> -0.87 | K39: =IF(C39="","",J39^2) -> 0.7569 | L39: =IF(C39="","",J39*H39) -> -1.8096 | M39: Hoja m
A40: 34 | B40: ='20 puntos (m)'!B10 -> 7 | C40: =IF('20 puntos (m)'!C10="","",'20 puntos (m)'!C10) -> -68.7 | D40: =IF(C40="","",B40*C40) -> -480.9 | E40: =IF(C40="","",B40^2) -> 49 | F40: =IF(C40="","",$O$15*B40+$O$16) -> -67.767265 | G40: =IF(C40="","",(C40-F40)^2) -> 0.86999476 | H40: =IF(C40="","",C40-$O$11) -> -1.12 | I40: =IF(C40="","",H40^2) -> 1.2544 | J40: =IF(C40="","",B40-$O$10) -> 0.13 | K40: =IF(C40="","",J40^2) -> 0.0169 | L40: =IF(C40="","",J40*H40) -> -0.1456 | M40: Hoja m
A41: 35 | B41: ='20 puntos (m)'!B11 -> 8 | C41: =IF('20 puntos (m)'!C11="","",'20 puntos (m)'!C11) -> -74.7 | D41: =IF(C41="","",B41*C41) -> -597.6 | E41: =IF(C41="","",B41^2) -> 64 | F41: =IF(C41="","",$O$15*B41+$O$16) -> -69.207764 | G41: =IF(C41="","",(C41-F41)^2) -> 30.164654 | H41: =IF(C41="","",C41-$O$11) -> -7.12 | I41: =IF(C41="","",H41^2) -> 50.6944 | J41: =IF(C41="","",B41-$O$10) -> 1.13 | K41: =IF(C41="","",J41^2) -> 1.2769 | L41: =IF(C41="","",J41*H41) -> -8.0456 | M41: Hoja m
A42: 36 | B42: ='20 puntos (m)'!B12 -> 9 | C42: =IF('20 puntos (m)'!C12="","",'20 puntos (m)'!C12) -> -85.6 | D42: =IF(C42="","",B42*C42) -> -770.4 | E42: =IF(C42="","",B42^2) -> 81 | F42: =IF(C42="","",$O$15*B42+$O$16) -> -70.648263 | G42: =IF(C42="","",(C42-F42)^2) -> 223.55443 | H42: =IF(C42="","",C42-$O$11) -> -18.02 | I42: =IF(C42="","",H42^2) -> 324.7204 | J42: =IF(C42="","",B42-$O$10) -> 2.13 | K42: =IF(C42="","",J42^2) -> 4.5369 | L42: =IF(C42="","",J42*H42) -> -38.3826 | M42: Hoja m
A43: 37 | B43: ='20 puntos (m)'!B13 -> 10 | C43: =IF('20 puntos (m)'!C13="","",'20 puntos (m)'!C13) -> -79.5 | D43: =IF(C43="","",B43*C43) -> -795 | E43: =IF(C43="","",B43^2) -> 100 | F43: =IF(C43="","",$O$15*B43+$O$16) -> -72.088763 | G43: =IF(C43="","",(C43-F43)^2) -> 54.926438 | H43: =IF(C43="","",C43-$O$11) -> -11.92 | I43: =IF(C43="","",H43^2) -> 142.0864 | J43: =IF(C43="","",B43-$O$10) -> 3.13 | K43: =IF(C43="","",J43^2) -> 9.7969 | L43: =IF(C43="","",J43*H43) -> -37.3096 | M43: Hoja m
...
